[2025-04-22T04:20:19.163-0400] {local_task_job_runner.py:123} INFO - ::group::Pre task execution logs
[2025-04-22T04:20:19.168-0400] {taskinstance.py:2614} INFO - Dependencies all met for dep_context=non-requeueable deps ti=<TaskInstance: fashion_data_pipeline.execute_notebook manual__2025-04-22T08:20:15.409277+00:00 [queued]>
[2025-04-22T04:20:19.172-0400] {taskinstance.py:2614} INFO - Dependencies all met for dep_context=requeueable deps ti=<TaskInstance: fashion_data_pipeline.execute_notebook manual__2025-04-22T08:20:15.409277+00:00 [queued]>
[2025-04-22T04:20:19.172-0400] {taskinstance.py:2867} INFO - Starting attempt 1 of 3
[2025-04-22T04:20:19.182-0400] {taskinstance.py:2890} INFO - Executing <Task(PythonOperator): execute_notebook> on 2025-04-22 08:20:15.409277+00:00
[2025-04-22T04:20:19.184-0400] {standard_task_runner.py:72} INFO - Started process 19270 to run task
[2025-04-22T04:20:19.187-0400] {standard_task_runner.py:104} INFO - Running: ['airflow', 'tasks', 'run', 'fashion_data_pipeline', 'execute_notebook', 'manual__2025-04-22T08:20:15.409277+00:00', '--job-id', '49', '--raw', '--subdir', 'DAGS_FOLDER/FashionData_DAG.py', '--cfg-path', '/tmp/tmp01pitxto']
[2025-04-22T04:20:19.187-0400] {standard_task_runner.py:105} INFO - Job 49: Subtask execute_notebook
[2025-04-22T04:20:19.219-0400] {task_command.py:467} INFO - Running <TaskInstance: fashion_data_pipeline.execute_notebook manual__2025-04-22T08:20:15.409277+00:00 [running]> on host BOOK-KTS1KMKSNJ.
[2025-04-22T04:20:19.268-0400] {taskinstance.py:3134} INFO - Exporting env vars: AIRFLOW_CTX_DAG_OWNER='airflow' AIRFLOW_CTX_DAG_ID='fashion_data_pipeline' AIRFLOW_CTX_TASK_ID='execute_notebook' AIRFLOW_CTX_EXECUTION_DATE='2025-04-22T08:20:15.409277+00:00' AIRFLOW_CTX_TRY_NUMBER='1' AIRFLOW_CTX_DAG_RUN_ID='manual__2025-04-22T08:20:15.409277+00:00'
[2025-04-22T04:20:19.269-0400] {logging_mixin.py:190} INFO - Task instance is in running state
[2025-04-22T04:20:19.269-0400] {logging_mixin.py:190} INFO -  Previous state of the Task instance: queued
[2025-04-22T04:20:19.270-0400] {logging_mixin.py:190} INFO - Current task name:execute_notebook state:running start_date:2025-04-22 08:20:19.169120+00:00
[2025-04-22T04:20:19.270-0400] {logging_mixin.py:190} INFO - Dag name:fashion_data_pipeline and current dag run status:running
[2025-04-22T04:20:19.270-0400] {taskinstance.py:732} INFO - ::endgroup::
[2025-04-22T04:20:19.271-0400] {FashionData_DAG.py:58} INFO - Executing notebook: /home/megin_mathew/airflow/notebooks/Fashion_Data_Pipeline.ipynb
[2025-04-22T04:20:19.271-0400] {FashionData_DAG.py:59} INFO - Output will be saved to: /home/megin_mathew/airflow/notebook_outputs/Fashion_Data_Pipeline-output-2025-04-22.ipynb
[2025-04-22T04:20:19.271-0400] {FashionData_DAG.py:60} INFO - Parameters passed to notebook: {'execution_date': '2025-04-22T08:20:15.409277+00:00', 'dag_run_id': 'manual__2025-04-22T08:20:15.409277+00:00', 'ds': '2025-04-22', 'ds_nodash': '20250422'}
[2025-04-22T04:20:19.271-0400] {execute.py:83} INFO - Input Notebook:  /home/megin_mathew/airflow/notebooks/Fashion_Data_Pipeline.ipynb
[2025-04-22T04:20:19.271-0400] {execute.py:84} INFO - Output Notebook: /home/megin_mathew/airflow/notebook_outputs/Fashion_Data_Pipeline-output-2025-04-22.ipynb
[2025-04-22T04:20:20.345-0400] {clientwrap.py:44} INFO - Executing notebook with kernel: python3
[2025-04-22T04:20:20.345-0400] {engines.py:223} INFO - Executing Cell 1---------------------------------------
[2025-04-22T04:20:20.353-0400] {engines.py:261} INFO - Ending Cell 1------------------------------------------
[2025-04-22T04:20:20.356-0400] {engines.py:223} INFO - Executing Cell 2---------------------------------------
[2025-04-22T04:20:20.362-0400] {engines.py:261} INFO - Ending Cell 2------------------------------------------
[2025-04-22T04:20:20.364-0400] {engines.py:223} INFO - Executing Cell 3---------------------------------------
[2025-04-22T04:20:20.935-0400] {clientwrap.py:91} INFO - Requirement already satisfied: kagglehub in ./airflow_venv/lib/python3.12/site-packages (0.3.11)
Requirement already satisfied: pandas in ./airflow_venv/lib/python3.12/site-packages (2.2.3)
Requirement already satisfied: psycopg2-binary in ./airflow_venv/lib/python3.12/site-packages (2.9.10)
Requirement already satisfied: sqlalchemy in ./airflow_venv/lib/python3.12/site-packages (1.4.54)
Requirement already satisfied: packaging in ./airflow_venv/lib/python3.12/site-packages (from kagglehub) (24.2)
Requirement already satisfied: pyyaml in ./airflow_venv/lib/python3.12/site-packages (from kagglehub) (6.0.2)
Requirement already satisfied: requests in ./airflow_venv/lib/python3.12/site-packages (from kagglehub) (2.32.3)
Requirement already satisfied: tqdm in ./airflow_venv/lib/python3.12/site-packages (from kagglehub) (4.67.1)
Requirement already satisfied: numpy>=1.26.0 in ./airflow_venv/lib/python3.12/site-packages (from pandas) (2.2.5)
Requirement already satisfied: python-dateutil>=2.8.2 in ./airflow_venv/lib/python3.12/site-packages (from pandas) (2.9.0.post0)
Requirement already satisfied: pytz>=2020.1 in ./airflow_venv/lib/python3.12/site-packages (from pandas) (2025.2)
Requirement already satisfied: tzdata>=2022.7 in ./airflow_venv/lib/python3.12/site-packages (from pandas) (2025.2)

[2025-04-22T04:20:20.985-0400] {clientwrap.py:91} INFO - Requirement already satisfied: greenlet!=0.4.17 in ./airflow_venv/lib/python3.12/site-packages (from sqlalchemy) (3.2.0)
Requirement already satisfied: six>=1.5 in ./airflow_venv/lib/python3.12/site-packages (from python-dateutil>=2.8.2->pandas) (1.17.0)
Requirement already satisfied: charset-normalizer<4,>=2 in ./airflow_venv/lib/python3.12/site-packages (from requests->kagglehub) (3.4.1)
Requirement already satisfied: idna<4,>=2.5 in ./airflow_venv/lib/python3.12/site-packages (from requests->kagglehub) (3.10)
Requirement already satisfied: urllib3<3,>=1.21.1 in ./airflow_venv/lib/python3.12/site-packages (from requests->kagglehub) (2.4.0)
Requirement already satisfied: certifi>=2017.4.17 in ./airflow_venv/lib/python3.12/site-packages (from requests->kagglehub) (2025.1.31)

[2025-04-22T04:20:21.384-0400] {engines.py:261} INFO - Ending Cell 3------------------------------------------
[2025-04-22T04:20:21.386-0400] {engines.py:223} INFO - Executing Cell 4---------------------------------------
[2025-04-22T04:20:21.470-0400] {clientwrap.py:91} INFO - ['KaggleDatasetAdapter', '__builtins__', '__cached__', '__doc__', '__file__', '__loader__', '__name__', '__package__', '__path__', '__spec__', '__version__', 'auth', 'cache', 'clients', 'colab_cache_resolver', 'competition', 'competition_download', 'config', 'dataset_download', 'dataset_load', 'dataset_upload', 'datasets', 'datasets_enums', 'datasets_helpers', 'env', 'exceptions', 'gcs_upload', 'get_package_asset_path', 'handle', 'http_resolver', 'integrity', 'kaggle_cache_resolver', 'kagglehub', 'load_dataset', 'logger', 'login', 'model_download', 'model_upload', 'models', 'models_helpers', 'notebook_output_download', 'notebooks', 'package_import', 'packages', 'registry', 'resolver', 'signing', 'tracker', 'utility_script_install', 'utility_scripts', 'whoami']

[2025-04-22T04:20:21.470-0400] {clientwrap.py:98} WARNING - /home/megin_mathew/airflow_venv/lib/python3.12/site-packages/tqdm/auto.py:21: TqdmWarning: IProgress not found. Please update jupyter and ipywidgets. See https://ipywidgets.readthedocs.io/en/stable/user_install.html
  from .autonotebook import tqdm as notebook_tqdm

[2025-04-22T04:20:21.471-0400] {engines.py:261} INFO - Ending Cell 4------------------------------------------
[2025-04-22T04:20:21.473-0400] {engines.py:223} INFO - Executing Cell 5---------------------------------------
[2025-04-22T04:20:21.937-0400] {clientwrap.py:91} INFO - Requirement already satisfied: kaggle in ./airflow_venv/lib/python3.12/site-packages (1.7.4.2)
Requirement already satisfied: bleach in ./airflow_venv/lib/python3.12/site-packages (from kaggle) (6.2.0)
Requirement already satisfied: certifi>=14.05.14 in ./airflow_venv/lib/python3.12/site-packages (from kaggle) (2025.1.31)
Requirement already satisfied: charset-normalizer in ./airflow_venv/lib/python3.12/site-packages (from kaggle) (3.4.1)
Requirement already satisfied: idna in ./airflow_venv/lib/python3.12/site-packages (from kaggle) (3.10)
Requirement already satisfied: protobuf in ./airflow_venv/lib/python3.12/site-packages (from kaggle) (5.29.4)
Requirement already satisfied: python-dateutil>=2.5.3 in ./airflow_venv/lib/python3.12/site-packages (from kaggle) (2.9.0.post0)
Requirement already satisfied: python-slugify in ./airflow_venv/lib/python3.12/site-packages (from kaggle) (8.0.4)
Requirement already satisfied: requests in ./airflow_venv/lib/python3.12/site-packages (from kaggle) (2.32.3)
Requirement already satisfied: setuptools>=21.0.0 in ./airflow_venv/lib/python3.12/site-packages (from kaggle) (79.0.0)
Requirement already satisfied: six>=1.10 in ./airflow_venv/lib/python3.12/site-packages (from kaggle) (1.17.0)
Requirement already satisfied: text-unidecode in ./airflow_venv/lib/python3.12/site-packages (from kaggle) (1.3)
Requirement already satisfied: tqdm in ./airflow_venv/lib/python3.12/site-packages (from kaggle) (4.67.1)
Requirement already satisfied: urllib3>=1.15.1 in ./airflow_venv/lib/python3.12/site-packages (from kaggle) (2.4.0)
Requirement already satisfied: webencodings in ./airflow_venv/lib/python3.12/site-packages (from kaggle) (0.5.1)

[2025-04-22T04:20:22.294-0400] {clientwrap.py:91} INFO - Note: you may need to restart the kernel to use updated packages.

[2025-04-22T04:20:22.296-0400] {engines.py:261} INFO - Ending Cell 5------------------------------------------
[2025-04-22T04:20:22.297-0400] {engines.py:223} INFO - Executing Cell 6---------------------------------------
[2025-04-22T04:20:22.385-0400] {clientwrap.py:91} INFO - Warning: Your Kaggle API key is readable by other users on this system! To fix this, you can run 'chmod 600 /home/megin_mathew/.config/kaggle/kaggle.json'
Kaggle module is successfully installed!

[2025-04-22T04:20:22.387-0400] {engines.py:261} INFO - Ending Cell 6------------------------------------------
[2025-04-22T04:20:22.389-0400] {engines.py:223} INFO - Executing Cell 7---------------------------------------
[2025-04-22T04:20:22.394-0400] {clientwrap.py:91} INFO - Warning: Your Kaggle API key is readable by other users on this system! To fix this, you can run 'chmod 600 /home/megin_mathew/.config/kaggle/kaggle.json'
Kaggle API authentication successful!

[2025-04-22T04:20:22.396-0400] {engines.py:261} INFO - Ending Cell 7------------------------------------------
[2025-04-22T04:20:22.398-0400] {engines.py:223} INFO - Executing Cell 8---------------------------------------
[2025-04-22T04:21:13.510-0400] {clientwrap.py:91} INFO - Downloaded: transactions.csv → Stored in: C:/Users/megin/fashion_dataset

[2025-04-22T04:21:17.195-0400] {clientwrap.py:98} WARNING - /home/megin_mathew/airflow_venv/lib/python3.12/site-packages/kagglehub/pandas_datasets.py:91: DtypeWarning: Columns (3) have mixed types. Specify dtype option on import or set low_memory=False.
  result = read_function(

[2025-04-22T04:21:20.828-0400] {clientwrap.py:91} INFO - Downloaded: customers.csv → Stored in: C:/Users/megin/fashion_dataset

[2025-04-22T04:21:21.212-0400] {clientwrap.py:91} INFO - Downloaded: discounts.csv → Stored in: C:/Users/megin/fashion_dataset

[2025-04-22T04:21:21.516-0400] {clientwrap.py:91} INFO - Downloaded: employees.csv → Stored in: C:/Users/megin/fashion_dataset

[2025-04-22T04:21:21.945-0400] {clientwrap.py:91} INFO - Downloaded: products.csv → Stored in: C:/Users/megin/fashion_dataset

[2025-04-22T04:21:22.020-0400] {clientwrap.py:91} INFO - Downloaded: stores.csv → Stored in: C:/Users/megin/fashion_dataset

[2025-04-22T04:21:22.025-0400] {engines.py:261} INFO - Ending Cell 8------------------------------------------
[2025-04-22T04:21:22.030-0400] {engines.py:223} INFO - Executing Cell 9---------------------------------------
[2025-04-22T04:21:22.044-0400] {engines.py:261} INFO - Ending Cell 9------------------------------------------
[2025-04-22T04:21:22.046-0400] {engines.py:223} INFO - Executing Cell 10--------------------------------------
[2025-04-22T04:21:22.048-0400] {engines.py:261} INFO - Ending Cell 10-----------------------------------------
[2025-04-22T04:21:22.050-0400] {engines.py:223} INFO - Executing Cell 11--------------------------------------
[2025-04-22T04:21:24.056-0400] {clientwrap.py:98} WARNING - 25/04/22 04:21:23 WARN Utils: Your hostname, BOOK-KTS1KMKSNJ resolves to a loopback address: 127.0.1.1; using 10.255.255.254 instead (on interface lo)
25/04/22 04:21:23 WARN Utils: Set SPARK_LOCAL_IP if you need to bind to another address

[2025-04-22T04:21:24.390-0400] {clientwrap.py:98} WARNING - Setting default log level to "WARN".
To adjust logging level use sc.setLogLevel(newLevel). For SparkR, use setLogLevel(newLevel).
25/04/22 04:21:24 WARN NativeCodeLoader: Unable to load native-hadoop library for your platform... using builtin-java classes where applicable

[2025-04-22T04:21:24.601-0400] {clientwrap.py:98} WARNING - 25/04/22 04:21:24 WARN SparkConf: Note that spark.local.dir will be overridden by the value set by the cluster manager (via SPARK_LOCAL_DIRS in mesos/standalone/kubernetes and LOCAL_DIRS in YARN).

[2025-04-22T04:21:24.997-0400] {clientwrap.py:98} WARNING - 25/04/22 04:21:24 WARN Utils: The configured local directories are not expected to be URIs; however, got suspicious values [D:/spark_temp]. Please check your configured local directories.

[2025-04-22T04:21:25.434-0400] {clientwrap.py:98} WARNING - 2025-04-22 04:21:25,431 - INFO - Starting data load process...

[2025-04-22T04:21:25.467-0400] {clientwrap.py:98} WARNING - 2025-04-22 04:21:25,465 - ERROR - Database setup failed: (psycopg2.OperationalError) connection to server at "10.255.255.254", port 5432 failed: Connection refused
	Is the server running on that host and accepting TCP/IP connections?

(Background on this error at: https://sqlalche.me/e/14/e3q8)

[2025-04-22T04:21:25.468-0400] {clientwrap.py:98} WARNING - 2025-04-22 04:21:25,466 - ERROR - Database error: Database setup failed
Traceback (most recent call last):
  File "/tmp/ipykernel_19272/3969976327.py", line 427, in load_data_to_postgres
    raise RuntimeError("Database setup failed")
RuntimeError: Database setup failed

[2025-04-22T04:21:25.808-0400] {clientwrap.py:98} WARNING - 2025-04-22 04:21:25,806 - ERROR - Fatal error: Database setup failed
Traceback (most recent call last):
  File "/tmp/ipykernel_19272/3969976327.py", line 492, in <module>
    load_data_to_postgres()
  File "/tmp/ipykernel_19272/3969976327.py", line 427, in load_data_to_postgres
    raise RuntimeError("Database setup failed")
RuntimeError: Database setup failed

[2025-04-22T04:21:25.811-0400] {engines.py:261} INFO - Ending Cell 11-----------------------------------------
[2025-04-22T04:21:25.814-0400] {engines.py:223} INFO - Executing Cell 12--------------------------------------
[2025-04-22T04:21:25.817-0400] {engines.py:261} INFO - Ending Cell 12-----------------------------------------
[2025-04-22T04:21:28.465-0400] {FashionData_DAG.py:79} INFO - Notebook execution completed successfully
[2025-04-22T04:21:28.467-0400] {python.py:240} INFO - Done. Returned value was: True
[2025-04-22T04:21:28.532-0400] {taskinstance.py:341} INFO - ::group::Post task execution logs
[2025-04-22T04:21:28.534-0400] {taskinstance.py:353} INFO - Marking task as SUCCESS. dag_id=fashion_data_pipeline, task_id=execute_notebook, run_id=manual__2025-04-22T08:20:15.409277+00:00, execution_date=20250422T082015, start_date=20250422T082019, end_date=20250422T082128
[2025-04-22T04:21:28.560-0400] {logging_mixin.py:190} INFO - Task instance in success state
[2025-04-22T04:21:28.560-0400] {logging_mixin.py:190} INFO -  Previous state of the Task instance: running
[2025-04-22T04:21:28.560-0400] {logging_mixin.py:190} INFO - Dag name:fashion_data_pipeline queued_at:2025-04-22 08:20:15.422487+00:00
[2025-04-22T04:21:28.561-0400] {logging_mixin.py:190} INFO - Task hostname:BOOK-KTS1KMKSNJ. operator:PythonOperator
[2025-04-22T04:21:28.606-0400] {local_task_job_runner.py:266} INFO - Task exited with return code 0
[2025-04-22T04:21:28.637-0400] {taskinstance.py:3901} INFO - 0 downstream tasks scheduled from follow-on schedule check
[2025-04-22T04:21:28.637-0400] {local_task_job_runner.py:245} INFO - ::endgroup::
